<?xml version="1.0" ?>
<robot name="iris_depth_camera">
  <joint name="iris_depth_camera__depth_camera_joint" type="fixed">
    <parent link="base_link"/>
    <child link="camera_link"/>
    <origin xyz="0.1   0    0.035" rpy="-1.5707 0 -1.5707"/>
    <axis xyz="0 0 0"/>
    <limit lower="0" upper="0" effort="0" velocity="0"/>
  </joint>
  <joint name="iris_depth_camera__iris__/imu_joint" type="fixed">
    <parent link="base_link"/>
    <child link="iris_depth_camera__iris__/imu_link"/>
    <origin xyz="0   0   0.02" rpy="0 0 0"/>
    <axis xyz="1 0 0"/>
    <limit lower="0.0" upper="0.0" effort="0.0" velocity="0.0"/>
  </joint>
  <joint name="iris_depth_camera__iris__rotor_0_joint" type="revolute">
    <parent link="base_link"/>
    <child link="iris_depth_camera__iris__rotor_0"/>
    <origin xyz="0.13  -0.22   0.023" rpy="0 0 0"/>
    <axis xyz="0 0 1"/>
    <limit lower="-1e+16" upper="1e+16" effort="0.0" velocity="0.0"/>
  </joint>
  <joint name="iris_depth_camera__iris__rotor_1_joint" type="revolute">
    <parent link="base_link"/>
    <child link="iris_depth_camera__iris__rotor_1"/>
    <origin xyz="-0.13   0.2    0.023" rpy="0 0 0"/>
    <axis xyz="0 0 1"/>
    <limit lower="-1e+16" upper="1e+16" effort="0.0" velocity="0.0"/>
  </joint>
  <joint name="iris_depth_camera__iris__rotor_2_joint" type="revolute">
    <parent link="base_link"/>
    <child link="iris_depth_camera__iris__rotor_2"/>
    <origin xyz="0.13  0.22  0.023" rpy="0 0 0"/>
    <axis xyz="0 0 1"/>
    <limit lower="-1e+16" upper="1e+16" effort="0.0" velocity="0.0"/>
  </joint>
  <joint name="iris_depth_camera__iris__rotor_3_joint" type="revolute">
    <parent link="base_link"/>
    <child link="iris_depth_camera__iris__rotor_3"/>
    <origin xyz="-0.13  -0.2    0.023" rpy="0 0 0"/>
    <axis xyz="0 0 1"/>
    <limit lower="-1e+16" upper="1e+16" effort="0.0" velocity="0.0"/>
  </joint>
  <joint name="iris_depth_camera__iris__gps0_joint" type="fixed">
    <parent link="base_link"/>
    <child link="iris_depth_camera__iris__gps0__link"/>
    <origin xyz="0.05 0   0.04" rpy="0 0 0"/>
    <axis xyz="0 0 0"/>
    <limit lower="0" upper="0" effort="0" velocity="0"/>
  </joint>
  <link name="base_link">
    <collision name="base_link_inertia_collision">
      <origin xyz="0 0 0" rpy="0 0 0"/>
      <geometry>
        <box size="0.47 0.47 0.11"/>
      </geometry>
    </collision>
    <visual name="base_link_inertia_visual">
      <origin xyz="0 0 0" rpy="0 0 0"/>
      <geometry>
        <mesh filename="package://px4_offboard/meshes/iris.stl" scale="1 1 1"/>
      </geometry>
    </visual>
  </link>
  <link name="iris_depth_camera__iris__/imu_link">
    <inertial>
      <mass value="0.015"/>
      <origin xyz="0 0 0" rpy="0 0 0"/>
      <inertia ixx="1e-05" ixy="0" ixz="0" iyy="1e-05" iyz="0" izz="1e-05"/>
    </inertial>
  </link>
  <link name="iris_depth_camera__iris__rotor_0">
    <inertial>
      <mass value="0.005"/>
      <origin xyz="0 0 0" rpy="0 0 0"/>
      <inertia ixx="9.75e-07" ixy="0" ixz="0" iyy="0.000273104" iyz="0" izz="0.000274004"/>
    </inertial>
    <collision name="iris_depth_camera__iris__rotor_0_collision">
      <origin xyz="0 0 0" rpy="0 0 0"/>
      <geometry>
        <cylinder radius="0.128" length="0.005"/>
      </geometry>
    </collision>
    <visual name="iris_depth_camera__iris__rotor_0_visual">
      <origin xyz="0 0 0" rpy="0 0 0"/>
      <geometry>
        <mesh filename="package://px4_offboard/meshes/iris_prop_ccw.dae" scale="1 1 1"/>
      </geometry>
    </visual>
  </link>
  <link name="iris_depth_camera__iris__rotor_1">
    <inertial>
      <mass value="0.005"/>
      <origin xyz="0 0 0" rpy="0 0 0"/>
      <inertia ixx="9.75e-07" ixy="0" ixz="0" iyy="0.000273104" iyz="0" izz="0.000274004"/>
    </inertial>
    <collision name="iris_depth_camera__iris__rotor_1_collision">
      <origin xyz="0 0 0" rpy="0 0 0"/>
      <geometry>
        <cylinder radius="0.128" length="0.005"/>
      </geometry>
    </collision>
    <visual name="iris_depth_camera__iris__rotor_1_visual">
      <origin xyz="0 0 0" rpy="0 0 0"/>
      <geometry>
        <mesh filename="package://px4_offboard/meshes/iris_prop_ccw.dae" scale="1 1 1"/>
      </geometry>
    </visual>
  </link>
  <link name="iris_depth_camera__iris__rotor_2">
    <inertial>
      <mass value="0.005"/>
      <origin xyz="0 0 0" rpy="0 0 0"/>
      <inertia ixx="9.75e-07" ixy="0" ixz="0" iyy="0.000273104" iyz="0" izz="0.000274004"/>
    </inertial>
    <collision name="iris_depth_camera__iris__rotor_2_collision">
      <origin xyz="0 0 0" rpy="0 0 0"/>
      <geometry>
        <cylinder radius="0.128" length="0.005"/>
      </geometry>
    </collision>
    <visual name="iris_depth_camera__iris__rotor_2_visual">
      <origin xyz="0 0 0" rpy="0 0 0"/>
      <geometry>
        <mesh filename="package://px4_offboard/meshes/iris_prop_cw.dae" scale="1 1 1"/>
      </geometry>
    </visual>
  </link>
  <link name="iris_depth_camera__iris__rotor_3">
    <inertial>
      <mass value="0.005"/>
      <origin xyz="0 0 0" rpy="0 0 0"/>
      <inertia ixx="9.75e-07" ixy="0" ixz="0" iyy="0.000273104" iyz="0" izz="0.000274004"/>
    </inertial>
    <collision name="iris_depth_camera__iris__rotor_3_collision">
      <origin xyz="0 0 0" rpy="0 0 0"/>
      <geometry>
        <cylinder radius="0.128" length="0.005"/>
      </geometry>
    </collision>
    <visual name="iris_depth_camera__iris__rotor_3_visual">
      <origin xyz="0 0 0" rpy="0 0 0"/>
      <geometry>
        <mesh filename="package://px4_offboard/meshes/iris_prop_cw.dae" scale="1 1 1"/>
      </geometry>
    </visual>
  </link>
  <link name="iris_depth_camera__iris__gps0__link">
    <inertial>
      <mass value="0.015"/>
      <origin xyz="0 0 0" rpy="0 0 0"/>
      <inertia ixx="1e-05" ixy="0" ixz="0" iyy="1e-05" iyz="0" izz="1e-05"/>
    </inertial>
    <visual name="iris_depth_camera__iris__gps0__visual">
      <origin xyz="0 0 0" rpy="0 0 0"/>
      <geometry>
        <cylinder radius="0.01" length="0.002"/>
      </geometry>
    </visual>
  </link>
  <link name="camera_link">
    <inertial>
      <mass value="0.01"/>
      <origin xyz="0.01  0.025 0.025" rpy="0 0 0"/>
      <inertia ixx="4.15e-6" ixy="0" ixz="0" iyy="2.407e-6" iyz="0" izz="2.407e-6"/>
    </inertial>
    <visual name="iris_depth_camera__depth_camera__visual">
      <origin xyz="0 0 0" rpy="0 0 0"/>
      <geometry>
        <mesh filename="package://px4_offboard/meshes/realsense.dae" scale="1.0 1.0 1.0"/>
      </geometry>
    </visual>
  </link>
</robot>
