<?xml version="1.0" ?>
<robot name="iris_depth_camera_1">
  <joint name="depth_camera_joint_1" type="fixed">
    <parent link="base_link_1"/>
    <child link="camera_link_1"/>
    <origin xyz="0.1   0    0.035" rpy="0 0 0"/>
    <axis xyz="0 0 0"/>
    <limit lower="0" upper="0" effort="0" velocity="0"/>
  </joint>
  <joint name="imu_joint_1" type="fixed">
    <parent link="base_link_1"/>
    <child link="imu_link_1"/>
    <origin xyz="0   0   0.02" rpy="0 0 0"/>
    <axis xyz="1 0 0"/>
    <limit lower="0.0" upper="0.0" effort="0.0" velocity="0.0"/>
    <dynamics damping="0.1"/> <!-- Add damping to IMU joints -->
  </joint>
  <joint name="rotor_0_joint_1" type="revolute">
    <parent link="base_link_1"/>
    <child link="rotor_0_1"/>
    <origin xyz="0.13  -0.22   0.023" rpy="0 0 0"/>
    <axis xyz="0 0 1"/>
    <limit lower="-1e+16" upper="1e+16" effort="0.0" velocity="0.0"/>
    <dynamics damping="0.1"/> <!-- Add damping to rotor joints -->
  </joint>
  <joint name="rotor_1_joint_1" type="revolute">
    <parent link="base_link_1"/>
    <child link="rotor_1_1"/>
    <origin xyz="-0.13   0.2    0.023" rpy="0 0 0"/>
    <axis xyz="0 0 1"/>
    <limit lower="-1e+16" upper="1e+16" effort="0.0" velocity="0.0"/>
    <dynamics damping="0.1"/> <!-- Add damping to rotor joints -->
  </joint>
  <joint name="rotor_2_joint_1" type="revolute">
    <parent link="base_link_1"/>
    <child link="rotor_2_1"/>
    <origin xyz="0.13  0.22  0.023" rpy="0 0 0"/>
    <axis xyz="0 0 1"/>
    <limit lower="-1e+16" upper="1e+16" effort="0.0" velocity="0.0"/>
    <dynamics damping="0.1"/> <!-- Add damping to rotor joints -->
  </joint>
  <joint name="rotor_3_joint_1" type="revolute">
    <parent link="base_link_1"/>
    <child link="rotor_3_1"/>
    <origin xyz="-0.13  -0.2    0.023" rpy="0 0 0"/>
    <axis xyz="0 0 1"/>
    <limit lower="-1e+16" upper="1e+16" effort="0.0" velocity="0.0"/>
    <dynamics damping="0.1"/> <!-- Add damping to rotor joints -->
  </joint>
  <joint name="gps0_joint_1" type="fixed">
    <parent link="base_link_1"/>
    <child link="gps0__link_1"/>
    <origin xyz="0.05 0   0.04" rpy="0 0 0"/>
    <axis xyz="0 0 0"/>
    <limit lower="0" upper="0" effort="0" velocity="0"/>
  </joint>
  <joint name="imu_joint_1" type="fixed">
    <parent link="base_link_1"/>
    <child link="imu_link_1"/>
    <origin xyz="0   0   0.02" rpy="0 0 0"/>
    <dynamics damping="0.1"/>  <!-- Adding a small damping value -->
  </joint>
  <link name="base_link_1">
    <collision name="base_link_inertia_collision_1">
      <origin xyz="0 0 0" rpy="0 0 0"/>
      <geometry>
        <box size="0.47 0.47 0.11"/>
      </geometry>
    </collision>
    <visual name="base_link_inertia_visual_1">
      <origin xyz="0 0 0" rpy="0 0 0"/>
      <geometry>
        <mesh filename="package://px4_offboard/meshes/iris.stl" scale="1 1 1"/>
      </geometry>
    </visual>
    <dynamics damping="0.1" friction="0.2"/> <!-- Adding linear damping and friction for stability -->
  </link>
  <link name="imu_link_1">
    <inertial>
      <mass value="0.2"/> <!-- Increase mass slightly for stability -->
      <origin xyz="0 0 0" rpy="0 0 0"/>
      <inertia ixx="2e-05" ixy="0" ixz="0" iyy="2e-05" iyz="0" izz="2e-05"/> <!-- Increase inertia values -->
    </inertial>
  </link>
  <link name="rotor_0_1">
    <inertial>
      <mass value="0.1"/>  <!-- Slightly increase mass -->
      <origin xyz="0 0 0" rpy="0 0 0"/>
      <inertia ixx="9.75e-07" ixy="0" ixz="0" iyy="0.000273104" iyz="0" izz="0.000274004"/>
    </inertial>
    <collision name="rotor_0_collision_1">
      <origin xyz="0 0 0" rpy="0 0 0"/>
      <geometry>
        <cylinder radius="0.128" length="0.005"/>
      </geometry>
    </collision>
    <visual name="rotor_0_visual_1">
      <origin xyz="0 0 0" rpy="0 0 0"/>
      <geometry>
        <mesh filename="package://px4_offboard/meshes/iris_prop_ccw.dae" scale="1 1 1"/>
      </geometry>
    </visual>
  </link>
  <link name="rotor_1_1">
    <inertial>
      <mass value="0.1"/>  <!-- Slightly increase mass -->
      <origin xyz="0 0 0" rpy="0 0 0"/>
      <inertia ixx="9.75e-07" ixy="0" ixz="0" iyy="0.000273104" iyz="0" izz="0.000274004"/>
    </inertial>
    <collision name="rotor_1_collision_1">
      <origin xyz="0 0 0" rpy="0 0 0"/>
      <geometry>
        <cylinder radius="0.128" length="0.005"/>
      </geometry>
    </collision>
    <visual name="rotor_1_visual_1">
      <origin xyz="0 0 0" rpy="0 0 0"/>
      <geometry>
        <mesh filename="package://px4_offboard/meshes/iris_prop_ccw.dae" scale="1 1 1"/>
      </geometry>
    </visual>
  </link>
  <link name="rotor_2_1">
    <inertial>
      <mass value="0.1"/>  <!-- Slightly increase mass -->
      <origin xyz="0 0 0" rpy="0 0 0"/>
      <inertia ixx="9.75e-07" ixy="0" ixz="0" iyy="0.000273104" iyz="0" izz="0.000274004"/>
    </inertial>
    <collision name="rotor_2_collision_1">
      <origin xyz="0 0 0" rpy="0 0 0"/>
      <geometry>
        <cylinder radius="0.128" length="0.005"/>
      </geometry>
    </collision>
    <visual name="rotor_2_visual_1">
      <origin xyz="0 0 0" rpy="0 0 0"/>
      <geometry>
        <mesh filename="package://px4_offboard/meshes/iris_prop_cw.dae" scale="1 1 1"/>
      </geometry>
    </visual>
  </link>
  <link name="rotor_3_1">
    <inertial>
      <mass value="0.1"/>  <!-- Slightly increase mass -->
      <origin xyz="0 0 0" rpy="0 0 0"/>
      <inertia ixx="9.75e-07" ixy="0" ixz="0" iyy="0.000273104" iyz="0" izz="0.000274004"/>
    </inertial>
    <collision name="rotor_3_collision_1">
      <origin xyz="0 0 0" rpy="0 0 0"/>
      <geometry>
        <cylinder radius="0.128" length="0.005"/>
      </geometry>
    </collision>
    <visual name="rotor_3_visual_1">
      <origin xyz="0 0 0" rpy="0 0 0"/>
      <geometry>
        <mesh filename="package://px4_offboard/meshes/iris_prop_cw.dae" scale="1 1 1"/>
      </geometry>
    </visual>
  </link>
  <link name="gps0__link_1">
    <inertial>
      <mass value="0.015"/>
      <origin xyz="0 0 0" rpy="0 0 0"/>
      <inertia ixx="1e-05" ixy="0" ixz="0" iyy="1e-05" iyz="0" izz="1e-05"/>
    </inertial>
    <visual name="gps0__visual_1">
      <origin xyz="0 0 0" rpy="0 0 0"/>
      <geometry>
        <cylinder radius="0.01" length="0.002"/>
      </geometry>
    </visual>
  </link>
  <link name="camera_link_1">
    <inertial>
      <mass value="0.1"/> <!-- Slightly increased mass for stability -->
      <origin xyz="0.01  0.025  0.025" rpy="0 0 0"/>
      <inertia ixx="5e-6" ixy="0" ixz="0" iyy="3e-6" iyz="0" izz="3e-6"/> <!-- Slightly increased inertia values -->
    </inertial>
    <dynamics damping="0.1"/> <!-- Add damping for stability -->
    <visual name="depth_camera__visual_1">
      <origin xyz="0 0 0" rpy="0 0 0"/>
      <geometry>
        <mesh filename="package://px4_offboard/meshes/realsense.dae" scale="1.0 1.0 1.0"/>
      </geometry>
    </visual>
  </link>
</robot>
